Workbook

Sheet اسماء الموظفين
H1: =TODAY() -> 45228
A3: م | B3: الرقم الوظيفي | C3: اسم الموظف | D3: النوع | E3: الجنسية | F3: تصنيف التذكرة | G3: رقم الهوية / الإقامة | H3: تاريخ انتهاء الهوية | I3: تاريخ الميلاد | J3: العمر | K3: المهنة فى الاقامة | L3: المسمي الوظيفي | M3: تاريخ بداية العمل | N3: مدة العقد | O3: تاريخ أخر عودة من الأجازة | P3: الموقع | Q3: المشروع | R3: القسم | S3: نوع الوظيفة | T3: مدة الدوام | U3: تاريخ بداية العقد | V3: تاريخ نهاية العقد | W3: تاريخ إنتهاء الشهادة الصحية | X3: رقم جواز السفر | Y3: تاريخ انتهاء جواز السفر | Z3: رقم الجوال | AA3: البريد الإلكتروني | AB3: رقم الحساب البنك (IBN) | AC3: رمز البنك | AD3: الرقم 700 | AE3: اسم الشركة | AF3: الكيان | AG3: تاريخ الإستقالة/ انهاء التعاقد | AH3: نوع الاستبعاد | AI3: ملاحظات | AJ3: نوع رخصة القيادة | AK3: انتهاء الرخصة | AL3: حالة الموظف
A4: =ROW()-3 -> 1 | B4: 1000 | C4: سلطان عبدالرحمن صالح الرزيحي | D4: ذكر | E4: سعودي | F4: مواطن | G4: 1023619636 | H4: 46903 | I4: 25459 | J4: =($H$1-I4)/365 -> 54.161644 | L4: رئيس مجلس الإدارة | M4: 37257 | N4: 2 | O4: 37257 | P4: الرياض | Q4: الإدارة | R4: مجلس الإدارة | S4: دوام كامل | V4: 44926 | Z4: 050540082 | AB4: SA7310000004000000048604 | AC4: NCBK | AD4: 1023619636 | AE4: سلطان عبدالرحمن صالح الرزيحي | AI4: المالك | AL4: على رأس العمل
A5: =ROW()-3 -> 2 | B5: 1001 | C5: سنوار عبد المجيد | D5: ذكر | E5: بنجلاديش | F5: غير عربي | G5: 2183771753 | H5: 45269 | I5: 24108 | J5: =($H$1-I5)/365 -> 57.863014 | K5: عامل تعبئة رفوف | L5: مشرف فرع | M5: 37377 | N5: 2 | O5: 44130 | P5: الرياض | Q5: النسيم | R5: نقاط البيع | S5: دوام كامل | T5: 12 | V5: 45292 | X5: EJ0074623 | Y5: 46164 | Z5: 0541326417 | AA5: sanowar222ajs@gmail.com | AB5: SA4710000035762757000108 | AC5: NCBK | AD5: 7014477116 | AE5: شركة ريال البركة للتجارة | AF5: جملة ريال البركة | AL5: على رأس العمل
A6: =ROW()-3 -> 3 | B6: 1002 | C6: عبدالرحمن محمد عبده السلمي | D6: ذكر | E6: اليمن | F6: عربي | G6: 2278047721 | H6: 45367 | I6: 31189 | J6: =($H$1-I6)/365 -> 38.463014 | K6: مندوب مشتريات | L6: مندوب مشتريات | M6: 40165 | N6: 2 | O6: 42773 | P6: الرياض | Q6: جملة ريال البركة | R6: المشتريات | S6: دوام كامل | T6: 8 | V6: 45292 | X6: 07497058 | Y6: 45029 | Z6: 0534888345 | AB6: SA0810000028300000176502 | AC6: NCBK | AD6: 7014477116 | AE6: شركة ريال البركة للتجارة | AF6: جملة ريال البركة | AL6: على رأس العمل
A7: =ROW()-3 -> 4 | B7: 1003 | C7: سليم عبده علي الرعوي | D7: ذكر | E7: اليمن | F7: عربي | G7: 2258083357 | H7: 45428 | I7: 29587 | J7: =($H$1-I7)/365 -> 42.852055 | K7: مندوب مبيعات | L7: مشرف عام | M7: 40238 | N7: 2 | O7: 43259 | P7: الرياض | Q7: الإدارة | R7: المشتريات | S7: دوام كامل | T7: 8 | V7: 45444 | X7: 07496936 | Y7: 45029 | Z7: 0556069639 | AA7: salome109765@gmail.com | AB7: SA2510000037400000377404 | AC7: NCBK | AD7: 7014477116 | AE7: شركة ريال البركة للتجارة | AL7: على رأس العمل
A8: =ROW()-3 -> 5 | B8: 1004 | C8: مصطفى عبده علي صالح الرعوي | D8: ذكر | E8: اليمن | F8: عربي | G8: 2294076340 | H8: 45350 | I8: 29587 | J8: =($H$1-I8)/365 -> 42.852055 | K8: عامل مخزن | L8: مشرف أفرع | M8: 40337 | N8: 2 | O8: 40344 | P8: الرياض | Q8: جملة ريال البركة | R8: المشتريات | S8: دوام كامل | T8: 8 | V8: 45085 | X8: 03891773 | Y8: 46988 | Z8: 0504938015 | AA8: mustafa.riyal123@gmail.com | AB8: SA3510000028300000166510 | AC8: NCBK | AD8: 7014477116 | AE8: شركة ريال البركة للتجارة | AF8: جملة ريال البركة | AL8: على رأس العمل
A9: =ROW()-3 -> 6 | B9: 1005 | C9: عبدالسلام محمد سعيد ناجي | D9: ذكر | E9: اليمن | F9: عربي | G9: 2265219804 | H9: 45369 | I9: 31413 | J9: =($H$1-I9)/365 -> 37.849315 | K9: عامل تعبئة رفوف | L9: مشرف فرع | M9: 41244 | N9: 2 | O9: 44540 | P9: الرياض | Q9: فرع جده | R9: نقاط البيع | S9: دوام كامل | T9: 12 | V9: 44895 | X9: 06059233 | Y9: 46997 | Z9: 0556640381 | AA9: abdomohamed164@gmail.com | AB9: SA6710000028300000154003 | AC9: NCBK | AD9: 7009073037 | AE9: مؤسسة سلطان عبدالرحمن صالح الرزيحي للتجارة | AL9: على رأس العمل
A10: =ROW()-3 -> 7 | B10: 1006 | C10: بلال صالح حمود الفهد | D10: ذكر | E10: اليمن | F10: عربي | G10: 2259512115 | H10: 45249 | I10: 30682 | J10: =($H$1-I10)/365 -> 39.852055 | K10: عامل تعبئة رفوف | L10: مشرف فرع | M10: 41244 | N10: 2 | O10: 44635 | P10: الرياض | Q10: النسيم 2 | R10: نقاط البيع | S10: دوام كامل | T10: 12 | V10: 44895 | W10: 45014 | X10: 11308838 | Y10: 46910 | Z10: 0501647835 | AA10: belalalfahd285@gmail.com | AB10: SA0710000009800000191607 | AC10: NCBK | AD10: 7014477116 | AE10: شركة ريال البركة للتجارة | AF10: جملة ريال البركة | AL10: على رأس العمل
A11: =ROW()-3 -> 8 | B11: 1007 | C11: محمد عبدالدائم محمد عبدالرحمن | D11: ذكر | E11: اليمن | F11: عربي | G11: 2278571605 | H11: 45388 | I11: 31001 | J11: =($H$1-I11)/365 -> 38.978082 | K11: مندوب مبيعات | L11: مندوب مشتريات | M11: 41275 | N11: 2 | O11: 44663 | P11: الرياض | Q11: مستودع عكاظ 23 | R11: يعمل لحسابه | S11: دوام كامل | T11: 8 | V11: 44926 | X11: 09536880 | Y11: 46226 | Z11: 0567134029 | AC11: NCBK | AD11: 7014477116 | AE11: شركة ريال البركة للتجارة | AI11: المالك | AL11: على رأس العمل
A12: =ROW()-3 -> 9 | B12: 1008 | C12: فوزية هزال عيسى الهزال | D12: أنثى | E12: سعودي | F12: مواطن | G12: 1031868324 | I12: 24040 | J12: =($H$1-I12)/365 -> 58.049315 | K12: فني حسابات عام | L12: فني حسابات عام | M12: 41405 | N12: 2 | O12: 41405 | P12: الرياض | Q12: سعودة | R12: عمل عن بعد | S12: عن بعد | V12: 45056 | Z12: 0558077109 | AA12: noufsultan987@gmail.com | AB12: SA0480000195608010336522 | AC12: RJHI | AD12: 7014477116 | AE12: شركة ريال البركة للتجارة | AL12: على رأس العمل
A13: =ROW()-3 -> 10 | B13: 1009 | C13: اسد الزمان علي | D13: ذكر | E13: بنجلاديش | F13: غير عربي | G13: 2217477385 | H13: 45415 | I13: 23012 | J13: =($H$1-I13)/365 -> 60.865753 | K13: عامل تحميل وتنزيل | L13: عامل | M13: 41426 | N13: 2 | O13: 44783 | P13: الرياض | Q13: أونلاين | R13: نقاط البيع | S13: دوام كامل | T13: 8 | V13: 44926 | X13: EA0954167 | Y13: 45453 | Z13: 0573397800 | AB13: SA6880000537608016047187 | AC13: RJHI | AD13: 7014477116 | AE13: شركة ريال البركة للتجارة | AF13: جملة ريال البركة | AL13: على رأس العمل
A14: =ROW()-3 -> 11 | B14: 1010 | C14: تفضل ولي | D14: ذكر | E14: بنجلاديش | F14: غير عربي | G14: 2201478860 | H14: 45457 | I14: 24838 | J14: =($H$1-I14)/365 -> 55.863014 | K14: عامل تحميل وتنزيل | L14: عامل | M14: 41426 | N14: 2 | O14: 44626 | P14: الرياض | Q14: مستودع جملة سلطان والسويلم | R14: نقاط البيع | S14: دوام كامل | T14: 12 | V14: 44926 | X14: EA0957049 | Y14: 45483 | Z14: 0536523775 | AA14: zafor2220@gmail.com | AB14: SA3910000028300000148202 | AC14: NCBK | AD14: 7009073037 | AE14: مؤسسة سلطان عبدالرحمن صالح الرزيحي للتجارة | AF14: جملة سلطان | AL14: على رأس العمل
A15: =ROW()-3 -> 12 | B15: 1011 | C15: أيمن محمد فتحي خلف | D15: ذكر | E15: مصر | F15: عربي | G15: 2368855538 | H15: 45283 | I15: 32049 | J15: =($H$1-I15)/365 -> 36.106849 | K15: محاسب عام | L15: رئيس حسابات | M15: 45082 | N15: 2 | O15: 45185 | P15: الرياض | Q15: قضمة | R15: المالية | S15: تحت التجربة | T15: 8 | U15: 45082 | V15: 45447 | Z15: 0535124131 | AA15: aymanmorgan56@gmail.com | AB15: SA5030400108069269500011 | AC15: ANB | AD15: 7009073037 | AE15: مؤسسة سلطان عبدالرحمن صالح الرزيحي للتجارة | AL15: على رأس العمل
A16: =ROW()-3 -> 13 | B16: 1012 | C16: نوبي امير شيخ | D16: ذكر | E16: الهند | F16: غير عربي | G16: 2280543253 | H16: 45254 | I16: 29550 | J16: =($H$1-I16)/365 -> 42.953425 | K16: عامل تعبئة رفوف | L16: عامل | M16: 41975 | N16: 2 | O16: 44703 | P16: الدمام | Q16: العنود | R16: نقاط البيع | S16: دوام كامل | T16: 12 | V16: 44896 | X16: S1257358 | Y16: 46753 | Z16: 0503547269 | AB16: SA8010000028300000155903 | AC16: NCBK | AD16: 7014477116 | AE16: شركة ريال البركة للتجارة | AF16: جملة ريال البركة | AL16: على رأس العمل
A17: =ROW()-3 -> 14 | B17: 1013 | C17: منال سلطان عبدالرحمن الرزيحي | D17: أنثى | E17: سعودي | F17: مواطن | G17: 1092729258 | I17: 34878 | J17: =($H$1-I17)/365 -> 28.356164 | K17: مندوب مبيعات | L17: مندوب مبيعات | M17: 42036 | N17: 2 | O17: 42036 | P17: الرياض | Q17: سعودة | R17: عمل عن بعد | S17: عن بعد | V17: 44957 | Z17: 0500023185 | AB17: SA7480000195608010453699 | AC17: RJHI | AD17: 7014477116 | AE17: شركة ريال البركة للتجارة | AL17: على رأس العمل
A18: =ROW()-3 -> 15 | B18: 1014 | C18: منيره سلطان عبدالرحمن الرزيحي | D18: أنثى | E18: سعودي | F18: مواطن | G18: 1092729241 | I18: 34715 | J18: =($H$1-I18)/365 -> 28.80274 | K18: مندوب مبيعات | L18: مندوب مبيعات | M18: 42036 | N18: 2 | O18: 42036 | P18: الرياض | Q18: وكالة ممكن حلول | R18: التسويق | S18: دوام كامل | V18: 44957 | Z18: 0550332117 | AA18: munira.al-rezihi@hotmail.com | AB18: SA4110000074500002899007 | AC18: NCBK | AD18: 7014477116 | AE18: شركة ريال البركة للتجارة | AL18: على رأس العمل
A19: =ROW()-3 -> 16 | B19: 1015 | C19: عجيب بيلافي | D19: ذكر | E19: الهند | F19: غير عربي | G19: 2489500492 | H19: 45379 | I19: 36557 | J19: =($H$1-I19)/365 -> 23.756164 | K19: عامل تعبئة رفوف | L19: سائق دينا | M19: 42105 | N19: 2 | O19: 45173 | P19: الرياض | Q19: جملة ريال البركة | R19: نقاط البيع | S19: دوام كامل | T19: 8 | V19: 45026 | X19: T8662223 | Y19: 47420 | Z19: 0571201560 | AA19: ajeebajee603@gmail.com | AB19: SA5610000029600000504209 | AC19: NCBK | AD19: 7014477116 | AE19: شركة ريال البركة للتجارة | AF19: جملة ريال البركة | AL19: على رأس العمل
A20: =ROW()-3 -> 17 | B20: 1016 | C20: معشوق أحمد أنصاري | D20: ذكر | E20: هندي | F20: غير عربي | G20: 2393348749 | H20: 45394 | I20: 36587 | J20: =($H$1-I20)/365 -> 23.673973 | L20: سائق خاص | M20: 42105 | N20: 2 | P20: الرياض | Q20: جملة ريال البركة | R20: المنزل | S20: دوام كامل | V20: 45026 | Z20: 0540746137 | AB20: SA6080000537608016051114 | AC20: NCBK | AE20: سعد الرزيحي | AF20: جملة ريال البركة | AI20: المالك | AL20: على رأس العمل
A21: =ROW()-3 -> 18 | B21: 1017 | C21: جهانقير عبد الرزاق بادي | D21: ذكر | E21: بنجلاديش | F21: غير عربي | G21: 2249559515 | H21: 45285 | I21: 30531 | J21: =($H$1-I21)/365 -> 40.265753 | K21: عامل تعبئة رفوف | L21: عامل | M21: 41913 | N21: 2 | O21: 44368 | P21: الرياض | Q21: الدائري الغربي | R21: نقاط البيع | S21: دوام كامل | T21: 12 | V21: 45199 | X21: EF0750070 | Y21: 45726 | Z21: 0571842210 | AA21: jahangirpada12@gmail.com | AB21: SA6210000028300000153802 | AC21: NCBK | AD21: 7014477116 | AE21: شركة ريال البركة للتجارة | AF21: جملة ريال البركة | AL21: على رأس العمل
A22: =ROW()-3 -> 19 | B22: 1018 | C22: محمد عبدالله محمد الحبجي | D22: ذكر | E22: اليمن | F22: عربي | G22: 2465674733 | H22: 45315 | I22: 32509 | J22: =($H$1-I22)/365 -> 34.846575 | K22: مندوب مبيعات | L22: أمين صندوق | M22: 42401 | N22: 2 | O22: 44924 | P22: الرياض | Q22: الإدارة | R22: المالية | S22: دوام كامل | T22: 8 | V22: 44957 | X22: 10669885 | Y22: 46581 | Z22: 0556913618 | AA22: mohammed.alhmeikani.rb@gmail.com | AB22: SA7980000195608010695430 | AC22: RJHI | AD22: 7014477116 | AE22: شركة ريال البركة للتجارة | AL22: على رأس العمل
A23: =ROW()-3 -> 20 | B23: 1019 | C23: رؤوف انصاري سفيدة | D23: ذكر | E23: نيبال | F23: غير عربي | G23: 2341519797 | H23: 45240 | I23: 28942 | J23: =($H$1-I23)/365 -> 44.619178 | K23: عامل نظافة نوافذ | L23: عامل | M23: 42472 | N23: 2 | O23: 44703 | P23: الخرج | Q23: المصنع | R23: المناديل | S23: دوام كامل | T23: 12 | V23: 45027 | W23: 45144 | X23: 12268346 | Y23: 48031 | Z23: 0571940321 | AB23: SA9280000639608016086372 | AC23: RJHI | AD23: 7014477116 | AE23: شركة ريال البركة للتجارة | AF23: مصنع المناديل | AL23: على رأس العمل
A24: =ROW()-3 -> 21 | B24: 1020 | C24: محمد فاروق خليل | D24: ذكر | E24: الهند | F24: غير عربي | G24: 2419016353 | H24: 45483 | I24: 22860 | J24: =($H$1-I24)/365 -> 61.282192 | K24: سائق خاص | L24: عامل | M24: 42644 | N24: 2 | O24: 44765 | P24: الرياض | Q24: المصنع | R24: المناديل | S24: دوام كامل | T24: 8 | V24: 45199 | X24: S7706190 | Y24: 46956 | Z24: 0576933414 | AB24: SA9280000639608016086372 | AC24: RJHI | AD24: 1061419220 | AE24: عبدالرحمن سلطان الرزيحي | AG24: 45217 | AH24: تم انهاء خدماته | AL24: استبعاد نهائي
A25: =ROW()-3 -> 22 | B25: 1021 | C25: ياسر عبدالولي قايد الغابري | D25: ذكر | E25: اليمن | F25: عربي | G25: 2466030422 | H25: 45320 | I25: 33431 | J25: =($H$1-I25)/365 -> 32.320548 | K25: مندوب مبيعات | L25: مسؤول المتجر الإلكتروني | M25: 42675 | N25: 2 | O25: 44369 | P25: الرياض | Q25: وكالة ممكن حلول | R25: التجارة الإلكترونية | S25: دوام كامل | T25: 8 | V25: 44865 | X25: 08001001 | Y25: 45691 | Z25: 0509686482 | AA25: yasser4182@gmail.com | AB25: SA1880000195608010459654 | AC25: RJHI | AD25: 7014477116 | AE25: شركة ريال البركة للتجارة | AL25: على رأس العمل
A26: =ROW()-3 -> 23 | B26: 1022 | C26: عمر احمد علي الشامي | D26: ذكر | E26: اليمن | F26: عربي | G26: 2214431989 | H26: 45423 | I26: 29587 | J26: =($H$1-I26)/365 -> 42.852055 | K26: سائق شاحنة صغيرة | L26: أمين مستودع | M26: 42693 | N26: 2 | O26: 44693 | P26: الرياض | Q26: جملة ريال البركة | R26: نقاط البيع | S26: دوام كامل | T26: 8 | V26: 44883 | X26: 07289644 | Y26: 45255 | Z26: 0538003981 | AA26: alshamio907@gmail.com | AB26: SA7810000028300000176600 | AC26: NCBK | AD26: 7014477116 | AE26: شركة ريال البركة للتجارة | AF26: جملة ريال البركة | AL26: على رأس العمل
A27: =ROW()-3 -> 24 | B27: 1023 | C27: عبدالرحمن سلطان الرزيحي | D27: ذكر | E27: سعودي | F27: مواطن | G27: 1061419220 | I27: 32625 | J27: =($H$1-I27)/365 -> 34.528767 | L27: المدير العام | M27: 42705 | N27: 2 | O27: 42705 | P27: الرياض | Q27: الإدارة | R27: مجلس الإدارة | S27: دوام كامل | T27: 8 | V27: 44957 | Z27: 0597749776 | AA27: gm.riyal1@gmail.com | AB27: SA0680000640608010038368 | AC27: RJHI | AD27: 7014477116 | AE27: شركة ريال البركة للتجارة | AL27: على رأس العمل
A28: =ROW()-3 -> 25 | B28: 1024 | C28: إسماعيل دحدوح مياه | D28: ذكر | E28: بنجلاديش | F28: غير عربي | G28: 2184651574 | H28: 45373 | I28: 27760 | J28: =($H$1-I28)/365 -> 47.857534 | K28: عامل تحميل وتنزيل | L28: عامل | M28: 42725 | N28: 2 | O28: 44416 | P28: الرياض | Q28: جملة ريال البركة | R28: نقاط البيع | S28: دوام كامل | T28: 8 | V28: 44926 | X28: BQ0875119 | Y28: 46543 | Z28: 0552263817 | AB28: SA2210000028300000148605 | AC28: NCBK | AD28: 7014477116 | AE28: شركة ريال البركة للتجارة | AF28: جملة ريال البركة | AL28: على رأس العمل
A29: =ROW()-3 -> 26 | B29: 1025 | C29: فرهد حسين | D29: ذكر | E29: بنجلاديش | F29: غير عربي | G29: 2426108722 | H29: 45375 | I29: 34025 | J29: =($H$1-I29)/365 -> 30.693151 | K29: عامل تعبئة رفوف | L29: مشرف فرع | M29: 42736 | N29: 2 | O29: 42832 | P29: الرياض | Q29: الدائري الغربي | R29: نقاط البيع | S29: دوام كامل | T29: 12 | V29: 45077 | W29: 45043 | X29: EH0983921 | Y29: 46147 | Z29: 0578788036 | AA29: fh8262041@gmail.com | AB29: SA7530100942000097178330 | AC29: ARNB | AD29: 7014477116 | AE29: شركة ريال البركة للتجارة | AF29: جملة ريال البركة | AL29: على رأس العمل
A30: =ROW()-3 -> 27 | B30: 1026 | C30: أنور حسين | D30: ذكر | E30: بنجلاديش | F30: غير عربي | G30: 2425771561 | H30: 45380 | I30: 33270 | J30: =($H$1-I30)/365 -> 32.761644 | K30: عامل تعبئة رفوف | L30: عامل | M30: 42736 | N30: 2 | O30: 42744 | P30: الرياض | Q30: عنيزة | R30: نقاط البيع | S30: دوام كامل | T30: 12 | V30: 45077 | X30: EJ0522123 | Y30: 46269 | Z30: 0544326393 | AA30: baa461213@gmail.com | AB30: SA4010000028300000150803 | AC30: NCBK | AD30: 7014477116 | AE30: شركة ريال البركة للتجارة | AF30: جملة ريال البركة | AL30: على رأس العمل
A31: =ROW()-3 -> 28 | B31: 1027 | C31: محمد شيمون | D31: ذكر | E31: بنجلاديش | F31: غير عربي | G31: 2426599862 | H31: 45392 | I31: 34429 | J31: =($H$1-I31)/365 -> 29.586301 | K31: عامل تحميل وتنزيل | L31: عامل | M31: 42750 | N31: 2 | O31: 42832 | P31: الرياض | Q31: الدائري الغربي | R31: نقاط البيع | S31: دوام كامل | T31: 12 | V31: 45043 | W31: 45014 | X31: EL0008025 | Y31: 47043 | Z31: 0542327761 | AA31: md.sumon87726@gmail.com | AB31: SA0310000020100000425904 | AC31: NCBK | AD31: 7014477116 | AE31: شركة ريال البركة للتجارة | AF31: جملة ريال البركة | AL31: على رأس العمل
A32: =ROW()-3 -> 29 | B32: 1028 | C32: فاكي أحمد بري خان | D32: ذكر | E32: الهند | F32: غير عربي | G32: 2379964170 | H32: 45424 | I32: 30965 | J32: =($H$1-I32)/365 -> 39.076712 | K32: عامل تحميل وتنزيل | L32: عامل | M32: 42822 | N32: 2 | O32: 44706 | P32: الرياض | Q32: الدائري الغربي | R32: نقاط البيع | S32: دوام كامل | T32: 12 | V32: 45012 | W32: 45210 | X32: P1748466 | Y32: 46348 | Z32: 0548013957 | AA32: weekl14@gmail.com | AB32: SA5410000009800000192701 | AC32: NCBK | AD32: 7014477116 | AE32: شركة ريال البركة للتجارة | AF32: جملة ريال البركة | AL32: على رأس العمل
A33: =ROW()-3 -> 30 | B33: 1029 | C33: محمد رفيق الإسلام | D33: ذكر | E33: بنجلاديش | F33: غير عربي | G33: 2427581463 | H33: 45276 | I33: 32820 | J33: =($H$1-I33)/365 -> 33.994521 | K33: عامل تعبئة رفوف | L33: عامل | M33: 42856 | N33: 2 | O33: 44525 | P33: الخرج | Q33: غرناطة | R33: نقاط البيع | S33: دوام كامل | T33: 12 | V33: 45046 | W33: 44886 | X33: EH0105815 | Y33: 45958 | Z33: 0572457373 | AA33: ri7549484@gmail.com | AB33: SA5010000035700000038606 | AC33: NCBK | AD33: 7014477116 | AE33: شركة ريال البركة للتجارة | AF33: جملة ريال البركة | AL33: على رأس العمل
A34: =ROW()-3 -> 31 | B34: 1030 | C34: ميدى حسن | D34: ذكر | E34: بنجلاديش | F34: غير عربي | G34: 2429930478 | H34: 45357 | I34: 33290 | J34: =($H$1-I34)/365 -> 32.706849 | K34: عامل تعبئة رفوف | L34: عامل | M34: 42872 | N34: 2 | O34: 42941 | P34: الرياض | Q34: جملة ريال البركة | R34: نقاط البيع | S34: دوام كامل | T34: 8 | V34: 45428 | X34: EH0846338 | Y34: 46118 | Z34: 0571748299 | AB34: SA3410000009800000191509 | AC34: NCBK | AD34: 7014477116 | AE34: شركة ريال البركة للتجارة | AF34: جملة ريال البركة | AL34: على رأس العمل
A35: =ROW()-3 -> 32 | B35: 1031 | C35: أبو بكر عبد اللطيف | D35: ذكر | E35: بنجلاديش | F35: غير عربي | G35: 2434409518 | H35: 45272 | I35: 32599 | J35: =($H$1-I35)/365 -> 34.6 | K35: عامل تعبئة رفوف | L35: عامل | M35: 42933 | N35: 2 | O35: 44638 | P35: الرياض | Q35: الشفا | R35: نقاط البيع | S35: دوام كامل | T35: 12 | V35: 45093 | W35: 45013 | X35: EA0948816 | Y35: 45483 | Z35: 0560530376 | AB35: SA3680000195608010459621 | AC35: RJHI | AD35: 7015572543 | AE35: مؤسسة عبدالرحمن سلطان عبدالرحمن الرزيحي للتجارة | AF35: جملة ريال البركة | AL35: على رأس العمل
A36: =ROW()-3 -> 33 | B36: 1032 | C36: حمزه الاحمر | D36: ذكر | E36: سوريا | F36: عربي | G36: 2088386467 | H36: 45365 | I36: 29587 | J36: =($H$1-I36)/365 -> 42.852055 | K36: مندوب مبيعات | L36: مندوب مبيعات | M36: 42933 | N36: 2 | O36: 43771 | P36: الرياض | Q36: مستودع جملة سلطان والسويلم | R36: نقاط البيع | S36: دوام كامل | T36: 8 | V36: 45093 | X36: N013347938 | Y36: 45782 | Z36: 0533563369 | AB36: SA3910000004000000017109 | AC36: NCBK | AD36: 7014477116 | AE36: شركة ريال البركة للتجارة | AF36: جملة سلطان | AL36: على رأس العمل
A37: =ROW()-3 -> 34 | B37: 1033 | C37: محمد بارفيج محمد أكتير | D37: ذكر | E37: بنجلاديش | F37: غير عربي | G37: 2442201907 | H37: 45513 | I37: 34840 | J37: =($H$1-I37)/365 -> 28.460274 | K37: سائق خاص | L37: عامل | M37: 42948 | N37: 2 | P37: الرياض | Q37: جملة ريال البركة | R37: نقاط البيع | S37: كفالة شخصية | V37: 45169 | X37: EJ0281433 | Y37: 46189 | Z37: 0573284902 | AB37: SA9210000028300000148703 | AC37: NCBK | AD37: 1061419220 | AE37: عبدالرحمن سلطان الرزيحي | AF37: جملة ريال البركة | AL37: على رأس العمل
A38: =ROW()-3 -> 35 | B38: 1034 | C38: مد ميلون باطوري | D38: ذكر | E38: بنجلاديش | F38: غير عربي | G38: 2439079886 | H38: 45386 | I38: 34699 | J38: =($H$1-I38)/365 -> 28.846575 | K38: عامل تحميل وتنزيل | L38: سائق توصيل طلبات | M38: 42956 | N38: 2 | O38: 44417 | P38: الرياض | Q38: أونلاين | R38: نقاط البيع | S38: دوام كامل | T38: 8 | V38: 45146 | X38: A01780927 | Y38: 48096 | Z38: 0559331046 | AA38: milompatwary@gmail.com | AB38: SA5480000355608019366179 | AC38: RJHI | AD38: 7014477116 | AE38: شركة ريال البركة للتجارة | AF38: جملة ريال البركة | AL38: على رأس العمل
A39: =ROW()-3 -> 36 | B39: 1035 | C39: شاهين هولدير | D39: ذكر | E39: بنجلاديش | F39: غير عربي | G39: 2348234200 | H39: 45256 | I39: 32178 | J39: =($H$1-I39)/365 -> 35.753425 | K39: عامل تعبئة رفوف | L39: عامل | M39: 42914 | N39: 2 | O39: 43841 | P39: القصيم | Q39: بريدة | R39: نقاط البيع | S39: دوام كامل | T39: 12 | V39: 45104 | X39: EG0940110 | Y39: 45929 | Z39: 0573473765 | AA39: shahin09877@gmail.com | AB39: SA5510000028300000151309 | AC39: NCBK | AD39: 7014477116 | AE39: شركة ريال البركة للتجارة | AF39: جملة ريال البركة | AH39: أجازه سنوية | AL39: على رأس العمل
A40: =ROW()-3 -> 37 | B40: 1036 | C40: عارف نور الإسلام | D40: ذكر | E40: بنجلاديش | F40: غير عربي | G40: 2436104687 | H40: 45381 | I40: 33239 | J40: =($H$1-I40)/365 -> 32.846575 | K40: عامل تحميل وتنزيل | L40: عامل | M40: 42997 | N40: 2 | O40: 45164 | P40: الدمام | Q40: العنود | R40: نقاط البيع | S40: دوام كامل | T40: 12 | V40: 44822 | X40: EH0001454 | Y40: 45936 | Z40: 0550301681 | AB40: SA7710000009800000191705 | AC40: NCBK | AD40: 7014477116 | AE40: شركة ريال البركة للتجارة | AF40: جملة ريال البركة | AL40: على رأس العمل
A41: =ROW()-3 -> 38 | B41: 1037 | C41: نوف عبدالرحمن صالح الرزيحي | D41: أنثى | E41: سعودي | F41: مواطن | G41: 1060845557 | I41: 28647 | J41: =($H$1-I41)/365 -> 45.427397 | K41: مندوب مبيعات | L41: مندوب مبيعات | M41: 43018 | N41: 2 | O41: 43018 | P41: الرياض | Q41: سعودة | R41: عمل عن بعد | S41: عن بعد | V41: 44843 | Z41: 0506101789 | AB41: SA1680000369608010975469 | AC41: RJHI | AD41: 7014477116 | AE41: شركة ريال البركة للتجارة | AL41: على رأس العمل
...

Sheet بـيـان مرتبات
A3: م | B3: الرقم الوظيفي | C3: رقم الهوية | D3: نوع التحويل | E3: أسم الموظف | F3: المشروع | G3: الراتب الأساسي | H3: بدل السكن | I3: بدل الانتقال | J3: بدل معيشة | K3: بدلات أخرى | L3: اجمالي الراتب | M3: الشركة
A4: =ROW()-3 -> 1 | B4: 1000 | C4: 1023619636 | D4: تحويل خاص | E4: سلطان عبدالرحمن صالح الرزيحي | F4: الإدارة | G4: 35000 | H4: 16250 | I4: 0 | J4: 0 | K4: 38750 | L4: 90000 | M4: سلطان عبدالرحمن صالح الرزيحي
A5: =ROW()-3 -> 2 | B5: 1001 | C5: 2183771753 | D5: تحويل بنك | E5: سنوار عبد المجيد | F5: النسيم | G5: 1800 | H5: 0 | I5: 0 | J5: 0 | K5: 1200 | L5: 3000 | M5: شركة ريال البركة للتجارة
A6: =ROW()-3 -> 3 | B6: 1002 | C6: 2278047721 | D6: تحويل بنك | E6: عبدالرحمن محمد عبده السلمي | F6: جملة ريال البركة | G6: 3600 | H6: 0 | J6: 0 | K6: 6400 | L6: 10000 | M6: شركة ريال البركة للتجارة
A7: =ROW()-3 -> 4 | B7: 1003 | C7: 2258083357 | D7: تحويل بنك | E7: سليم عبده علي الرعوي | F7: الإدارة | G7: 3600 | H7: 0 | I7: 0 | J7: 0 | K7: 6400 | L7: 10000 | M7: شركة ريال البركة للتجارة
A8: =ROW()-3 -> 5 | B8: 1004 | C8: 2294076340 | D8: تحويل بنك | E8: مصطفى عبده علي صالح الرعوي | F8: جملة ريال البركة | G8: 3600 | H8: 0 | J8: 0 | K8: 6400 | L8: 10000 | M8: شركة ريال البركة للتجارة
A9: =ROW()-3 -> 6 | B9: 1005 | C9: 2265219804 | D9: تحويل بنك | E9: عبدالسلام محمد سعيد ناجي | F9: فرع جده | G9: 2500 | H9: 0 | J9: 0 | K9: 3500 | L9: 6000 | M9: مؤسسة سلطان عبدالرحمن صالح الرزيحي للتجارة
A10: =ROW()-3 -> 7 | B10: 1006 | C10: 2259512115 | D10: تحويل بنك | E10: بلال صالح حمود الفهد | F10: النسيم 2 | G10: 2000 | H10: 0 | J10: 0 | K10: 800 | L10: 2800 | M10: شركة ريال البركة للتجارة
A11: =ROW()-3 -> 8 | B11: 1007 | C11: 2278571605 | D11: تحويل بنك | E11: محمد عبدالدائم محمد عبدالرحمن | F11: مستودع عكاظ 23 | G11: 1000 | H11: 0 | K11: 0 | L11: 1000 | M11: شركة ريال البركة للتجارة
A12: =ROW()-3 -> 9 | B12: 1008 | C12: 1031868324 | D12: تحويل بنك | E12: فوزية هزال عيسى الهزال | F12: الإدارة | G12: 4000 | H12: 0 | I12: 0 | J12: 0 | K12: 0 | L12: 4000 | M12: شركة ريال البركة للتجارة
A13: =ROW()-3 -> 10 | B13: 1009 | C13: 2217477385 | D13: تحويل بنك | E13: اسد الزمان علي | F13: أونلاين | G13: 1600 | H13: 0 | J13: 0 | K13: 900 | L13: 2500 | M13: شركة ريال البركة للتجارة
A14: =ROW()-3 -> 11 | B14: 1010 | C14: 2201478860 | D14: تحويل بنك | E14: تفضل ولي | F14: مستودع جملة سلطان والسويلم | G14: 1600 | H14: 0 | J14: 0 | K14: 900 | L14: 2500 | M14: مؤسسة سلطان عبدالرحمن صالح الرزيحي للتجارة
A15: =ROW()-3 -> 12 | B15: 1011 | C15: 2368855538 | D15: تحويل بنك | E15: أيمن محمد فتحي خلف | F15: قضمة | G15: 4000 | H15: 0 | I15: 0 | J15: 0 | K15: 4000 | L15: 8000 | M15: مؤسسة سلطان عبدالرحمن صالح الرزيحي للتجارة
A16: =ROW()-3 -> 13 | B16: 1012 | C16: 2280543253 | D16: تحويل بنك | E16: نوبي امير شيخ | F16: العنود | G16: 1400 | H16: 0 | I16: 0 | J16: 0 | K16: 600 | L16: 2000 | M16: شركة ريال البركة للتجارة
A17: =ROW()-3 -> 14 | B17: 1013 | C17: 1092729258 | D17: تحويل بنك | E17: منال سلطان عبدالرحمن الرزيحي | F17: الإدارة | G17: 4000 | H17: 0 | I17: 0 | J17: 0 | K17: 0 | L17: 4000 | M17: شركة ريال البركة للتجارة
A18: =ROW()-3 -> 15 | B18: 1014 | C18: 1092729241 | D18: تحويل بنك | E18: منيره سلطان عبدالرحمن الرزيحي | F18: وكالة ممكن حلول | G18: 4000 | H18: 0 | I18: 0 | J18: 0 | K18: 500 | L18: 4500 | M18: شركة ريال البركة للتجارة
A19: =ROW()-3 -> 16 | B19: 1015 | C19: 2489500492 | D19: تحويل بنك | E19: عجيب بيلافي | F19: جملة ريال البركة | G19: 1600 | H19: 0 | J19: 0 | K19: 1200 | L19: 2800 | M19: شركة ريال البركة للتجارة
A20: =ROW()-3 -> 17 | B20: 1016 | C20: 2393348749 | D20: تحويل خاص | E20: معشوق أحمد أنصاري | F20: جملة ريال البركة | G20: 1500 | H20: 0 | J20: 0 | K20: 300 | L20: 1800 | M20: سعد الرزيحي
A21: =ROW()-3 -> 18 | B21: 1017 | C21: 2249559515 | D21: تحويل بنك | E21: جهانقير عبد الرزاق بادي | F21: الدائري الغربي | G21: 1300 | H21: 0 | I21: 0 | J21: 0 | K21: 700 | L21: 2000 | M21: شركة ريال البركة للتجارة
A22: =ROW()-3 -> 19 | B22: 1018 | C22: 2465674733 | D22: تحويل بنك | E22: محمد عبدالله محمد الحبجي | F22: الإدارة | G22: 2200 | H22: 0 | I22: 0 | J22: 0 | K22: 3300 | L22: 5500 | M22: شركة ريال البركة للتجارة
A23: =ROW()-3 -> 20 | B23: 1019 | C23: 2341519797 | D23: تحويل بنك | E23: رؤوف انصاري سفيدة | F23: المصنع | G23: 1400 | H23: 0 | J23: 0 | K23: 800 | L23: 2200 | M23: شركة ريال البركة للتجارة
A24: =ROW()-3 -> 21 | B24: 1020 | C24: 2419016353 | D24: تحويل خاص | E24: محمد فاروق خليل | F24: المصنع | G24: 1400 | H24: 0 | J24: 0 | K24: 300 | L24: 1700 | M24: عبدالرحمن سلطان الرزيحي
A25: =ROW()-3 -> 22 | B25: 1021 | C25: 2466030422 | D25: تحويل بنك | E25: ياسر عبدالولي قايد الغابري | F25: وكالة ممكن حلول | G25: 3600 | H25: 0 | J25: 0 | K25: 4400 | L25: 8000 | M25: شركة ريال البركة للتجارة
A26: =ROW()-3 -> 23 | B26: 1022 | C26: 2214431989 | D26: تحويل بنك | E26: عمر احمد علي الشامي | F26: جملة ريال البركة | G26: 2200 | H26: 0 | J26: 0 | K26: 2800 | L26: 5000 | M26: شركة ريال البركة للتجارة
A27: =ROW()-3 -> 24 | B27: 1023 | C27: 1061419220 | D27: تحويل بنك | E27: عبدالرحمن سلطان الرزيحي | F27: الإدارة | G27: 9600 | H27: 2400 | I27: 0 | J27: 0 | K27: 13000 | L27: 25000 | M27: شركة ريال البركة للتجارة
A28: =ROW()-3 -> 25 | B28: 1024 | C28: 2184651574 | D28: تحويل بنك | E28: إسماعيل دحدوح مياه | F28: جملة ريال البركة | G28: 1300 | H28: 0 | J28: 0 | K28: 700 | L28: 2000 | M28: شركة ريال البركة للتجارة
A29: =ROW()-3 -> 26 | B29: 1025 | C29: 2426108722 | D29: تحويل بنك | E29: فرهد حسين | F29: الدائري الغربي | G29: 1800 | H29: 0 | I29: 0 | J29: 0 | K29: 1200 | L29: 3000 | M29: شركة ريال البركة للتجارة
A30: =ROW()-3 -> 27 | B30: 1026 | C30: 2425771561 | D30: تحويل بنك | E30: أنور حسين | F30: عنيزة | G30: 1300 | H30: 0 | J30: 0 | K30: 1000 | L30: 2300 | M30: شركة ريال البركة للتجارة
A31: =ROW()-3 -> 28 | B31: 1027 | C31: 2426599862 | D31: تحويل بنك | E31: محمد شيمون | F31: الدائري الغربي | G31: 1400 | H31: 0 | I31: 0 | J31: 0 | K31: 900 | L31: 2300 | M31: شركة ريال البركة للتجارة
A32: =ROW()-3 -> 29 | B32: 1028 | C32: 2379964170 | D32: تحويل بنك | E32: فاكي أحمد بري خان | F32: الدائري الغربي | G32: 1500 | H32: 0 | I32: 0 | J32: 0 | K32: 700 | L32: 2200 | M32: شركة ريال البركة للتجارة
A33: =ROW()-3 -> 30 | B33: 1029 | C33: 2427581463 | D33: تحويل بنك | E33: محمد رفيق الإسلام | F33: غرناطة | G33: 1300 | H33: 0 | J33: 0 | K33: 1200 | L33: 2500 | M33: شركة ريال البركة للتجارة
A34: =ROW()-3 -> 31 | B34: 1030 | C34: 2429930478 | D34: تحويل بنك | E34: ميدى حسن | F34: جملة ريال البركة | G34: 1300 | H34: 0 | J34: 0 | K34: 1000 | L34: 2300 | M34: شركة ريال البركة للتجارة
A35: =ROW()-3 -> 32 | B35: 1031 | C35: 2434409518 | D35: تحويل بنك | E35: أبو بكر عبد اللطيف | F35: الشفا | G35: 1300 | H35: 0 | K35: 1000 | L35: 2300 | M35: مؤسسة عبدالرحمن سلطان عبدالرحمن الرزيحي للتجارة
A36: =ROW()-3 -> 33 | B36: 1032 | C36: 2088386467 | D36: تحويل بنك | E36: حمزه الاحمر | F36: مستودع جملة سلطان والسويلم | G36: 4000 | H36: 0 | J36: 0 | K36: 6000 | L36: 10000 | M36: شركة ريال البركة للتجارة
A37: =ROW()-3 -> 34 | B37: 1033 | C37: 2442201907 | D37: تحويل بنك | E37: محمد بارفيج محمد أكتير | F37: جملة ريال البركة | G37: 1300 | H37: 0 | J37: 0 | K37: 900 | L37: 2200 | M37: عبدالرحمن سلطان الرزيحي
A38: =ROW()-3 -> 35 | B38: 1034 | C38: 2439079886 | D38: تحويل بنك | E38: مد ميلون باطوري | F38: أونلاين | G38: 1500 | H38: 0 | J38: 0 | K38: 1000 | L38: 2500 | M38: شركة ريال البركة للتجارة
A39: =ROW()-3 -> 36 | B39: 1035 | C39: 2348234200 | D39: تحويل بنك | E39: شاهين هولدير | F39: بريدة | G39: 1400 | H39: 0 | J39: 0 | K39: 1100 | L39: 2500 | M39: شركة ريال البركة للتجارة
A40: =ROW()-3 -> 37 | B40: 1036 | C40: 2436104687 | D40: تحويل بنك | E40: عارف نور الإسلام | F40: العنود | G40: 1200 | H40: 0 | I40: 0 | J40: 0 | K40: 800 | L40: 2000 | M40: شركة ريال البركة للتجارة
A41: =ROW()-3 -> 38 | B41: 1037 | C41: 1060845557 | D41: تحويل بنك | E41: نوف عبدالرحمن صالح الرزيحي | F41: الإدارة | G41: 4000 | H41: 0 | J41: 0 | K41: 0 | L41: 4000 | M41: شركة ريال البركة للتجارة
A42: =ROW()-3 -> 39 | B42: 1038 | C42: 2439069309 | D42: تحويل بنك | E42: محمد عارف حسين | F42: غرناطة | G42: 1300 | H42: 0 | J42: 0 | K42: 900 | L42: 2200 | M42: شركة ريال البركة للتجارة
...

Sheet تكاليف السعودة
A1: كشف تكاليف الموظفين
A3: م | B3: الرقم الوظيفي | C3: أسم الموظف | D3: الشركة | E3: الراتب | F3: اشتراك التامينات الاجتماعية | G3: التامين الطبي | H3: مجموع التكلفة شهري | I3: حالة الموظف
A4: =ROW()-3 -> 1 | B4: 1008 | C4: =VLOOKUP(B4,'[1]اسماء الموظفين'!$B$8:$O$1001,2,0) -> فوزية هزال عيسي الهزال | D4: =VLOOKUP(B4,'[2]المقيمين النشطين'!$B$2:$Q$387,15,0) -> شركة ريال البركة للتجارة | E4: =VLOOKUP(B4,[3]سعودة!$B$9:$E$504,4,0) -> 2000 | F4: =4000*22% -> 880 | G4: =7652/12 -> 637.66667 | H4: =SUM(E4:G4) -> 3517.6667 | I4: =VLOOKUP(B4,'اسماء الموظفين'!B4:AL605,37,0) -> #N/A
A5: =ROW()-3 -> 2 | B5: 1013 | C5: =VLOOKUP(B5,'[1]اسماء الموظفين'!$B$8:$O$1001,2,0) -> منال سلطان عبدالرحمن الرزيحي | D5: =VLOOKUP(B5,'[2]المقيمين النشطين'!$B$2:$Q$387,15,0) -> شركة ريال البركة للتجارة | E5: =VLOOKUP(B5,[3]سعودة!$B$9:$E$504,4,0) -> 1000 | F5: =4000*22% -> 880 | H5: =SUM(E5:G5) -> 1880
A6: =ROW()-3 -> 3 | B6: 1037 | C6: =VLOOKUP(B6,'[1]اسماء الموظفين'!$B$8:$O$1001,2,0) -> نوف عبدالرحمن صالح الرزيحي | D6: =VLOOKUP(B6,'[2]المقيمين النشطين'!$B$2:$Q$387,15,0) -> شركة ريال البركة للتجارة | E6: =VLOOKUP(B6,[3]سعودة!$B$9:$E$504,4,0) -> 2000 | F6: =4000*22% -> 880 | H6: =SUM(E6:G6) -> 2880
A7: =ROW()-3 -> 4 | B7: 1040 | C7: =VLOOKUP(B7,'[1]اسماء الموظفين'!$B$8:$O$1001,2,0) -> فاطمه محمد عبدالعزيز الشليل | D7: =VLOOKUP(B7,'[2]المقيمين النشطين'!$B$2:$Q$387,15,0) -> شركة ريال البركة للتجارة | E7: =VLOOKUP(B7,[3]سعودة!$B$9:$E$504,4,0) -> 1000 | F7: =4000*22% -> 880 | G7: =655/12 -> 54.583333 | H7: =SUM(E7:G7) -> 1934.5833
A8: =ROW()-3 -> 5 | B8: 1042 | C8: =VLOOKUP(B8,'[1]اسماء الموظفين'!$B$8:$O$1001,2,0) -> هياء سليمان صالح المريشد | D8: =VLOOKUP(B8,'[2]المقيمين النشطين'!$B$2:$Q$387,15,0) -> شركة ريال البركة للتجارة | E8: =VLOOKUP(B8,[3]سعودة!$B$9:$E$504,4,0) -> 1000 | F8: =4000*22% -> 880 | G8: =596/12 -> 49.666667 | H8: =SUM(E8:G8) -> 1929.6667
A9: =ROW()-3 -> 6 | B9: 1046 | C9: =VLOOKUP(B9,'[1]اسماء الموظفين'!$B$8:$O$1001,2,0) -> سليمان صالح سليمان المريشد | D9: =VLOOKUP(B9,'[2]المقيمين النشطين'!$B$2:$Q$387,15,0) -> شركة ريال البركة للتجارة | E9: =VLOOKUP(B9,[3]سعودة!$B$9:$E$504,4,0) -> 1500 | F9: =4000*22% -> 880 | G9: =1229/12 -> 102.41667 | H9: =SUM(E9:G9) -> 2482.4167
A10: =ROW()-3 -> 7 | B10: 1101 | C10: =VLOOKUP(B10,'[1]اسماء الموظفين'!$B$8:$O$1001,2,0) -> فاطمة إبراهيم سعود العبودي | D10: =VLOOKUP(B10,'[2]المقيمين النشطين'!$B$2:$Q$387,15,0) -> شركة ريال البركة للتجارة | E10: =VLOOKUP(B10,[3]سعودة!$B$9:$E$504,4,0) -> 1000 | F10: =4000*22% -> 880 | G10: =596/12 -> 49.666667 | H10: =SUM(E10:G10) -> 1929.6667
A11: =ROW()-3 -> 8 | B11: 1103 | C11: =VLOOKUP(B11,'[1]اسماء الموظفين'!$B$8:$O$1001,2,0) -> شهد سلطان عبدالرحمن الرزيحي | D11: =VLOOKUP(B11,'[2]المقيمين النشطين'!$B$2:$Q$387,15,0) -> شركة ريال البركة للتجارة | E11: =VLOOKUP(B11,[3]سعودة!$B$9:$E$504,4,0) -> 1000 | F11: =4000*22% -> 880 | G11: =2019/12 -> 168.25 | H11: =SUM(E11:G11) -> 2048.25
A12: =ROW()-3 -> 9 | B12: 1121 | C12: =VLOOKUP(B12,'[1]اسماء الموظفين'!$B$8:$O$1001,2,0) -> عبدالله سعد عبدالرحمن الرزيحي | D12: =VLOOKUP(B12,'[2]المقيمين النشطين'!$B$2:$Q$387,15,0) -> مؤسسة عبدالرحمن سلطان عبدالرحمن الرزيحي للتجارة | E12: =VLOOKUP(B12,[3]سعودة!$B$9:$E$504,4,0) -> 1000 | F12: =4000*22% -> 880 | H12: =SUM(E12:G12) -> 1880
A13: =ROW()-3 -> 10 | B13: 1122 | C13: =VLOOKUP(B13,'[1]اسماء الموظفين'!$B$8:$O$1001,2,0) -> حصه خالد يوسف الزيد | D13: =VLOOKUP(B13,'[2]المقيمين النشطين'!$B$2:$Q$387,15,0) -> مؤسسة عبدالرحمن سلطان عبدالرحمن الرزيحي للتجارة | E13: =VLOOKUP(B13,[3]سعودة!$B$9:$E$504,4,0) -> 3000 | F13: =4000*22% -> 880 | H13: =SUM(E13:G13) -> 3880
A14: =ROW()-3 -> 11 | B14: 1146 | C14: =VLOOKUP(B14,'[1]اسماء الموظفين'!$B$8:$O$1001,2,0) -> مشاعل زيد زيدان الهلالي | D14: =VLOOKUP(B14,'[2]المقيمين النشطين'!$B$2:$Q$387,15,0) -> شركة ريال البركة للتجارة | E14: =VLOOKUP(B14,[3]سعودة!$B$9:$E$504,4,0) -> 1000 | F14: =4000*22% -> 880 | H14: =SUM(E14:G14) -> 1880
A15: =ROW()-3 -> 12 | B15: 1147 | C15: =VLOOKUP(B15,'[1]اسماء الموظفين'!$B$8:$O$1001,2,0) -> منيره حسن عبدالله قعود | D15: =VLOOKUP(B15,'[2]المقيمين النشطين'!$B$2:$Q$387,15,0) -> شركة ريال البركة للتجارة | E15: =VLOOKUP(B15,[3]سعودة!$B$9:$E$504,4,0) -> 1000 | F15: =4000*22% -> 880 | H15: =SUM(E15:G15) -> 1880
A16: =ROW()-3 -> 13 | B16: 1148 | C16: =VLOOKUP(B16,'[1]اسماء الموظفين'!$B$8:$O$1001,2,0) -> مرام ناصر عبدالرحمن السلمان | D16: =VLOOKUP(B16,'[2]المقيمين النشطين'!$B$2:$Q$387,15,0) -> شركة ريال البركة للتجارة | E16: =VLOOKUP(B16,[3]سعودة!$B$9:$E$504,4,0) -> 1000 | F16: =4000*22% -> 880 | H16: =SUM(E16:G16) -> 1880
A17: =ROW()-3 -> 14 | B17: 1149 | C17: =VLOOKUP(B17,'[1]اسماء الموظفين'!$B$8:$O$1001,2,0) -> أميرة احمد محمد السميح | D17: =VLOOKUP(B17,'[2]المقيمين النشطين'!$B$2:$Q$387,15,0) -> شركة أدفان للصناعة ( شركة شخص واحد ) | E17: =VLOOKUP(B17,[3]سعودة!$B$9:$E$504,4,0) -> 1000 | F17: =4000*22% -> 880 | H17: =SUM(E17:G17) -> 1880
A18: =ROW()-3 -> 15 | B18: 1150 | C18: =VLOOKUP(B18,'[1]اسماء الموظفين'!$B$8:$O$1001,2,0) -> نوره عبدالعزيز حسين ابوساق | D18: =VLOOKUP(B18,'[2]المقيمين النشطين'!$B$2:$Q$387,15,0) -> شركة أدفان للصناعة ( شركة شخص واحد ) | E18: =VLOOKUP(B18,[3]سعودة!$B$9:$E$504,4,0) -> 1000 | F18: =4000*22% -> 880 | H18: =SUM(E18:G18) -> 1880
A19: =ROW()-3 -> 16 | B19: 1151 | C19: =VLOOKUP(B19,'[1]اسماء الموظفين'!$B$8:$O$1001,2,0) -> ريم عبدالعزيز حسين أبوساق | D19: =VLOOKUP(B19,'[2]المقيمين النشطين'!$B$2:$Q$387,15,0) -> مؤسسة سلطان عبدالرحمن صالح الرزيحي للتجارة | E19: =VLOOKUP(B19,[3]سعودة!$B$9:$E$504,4,0) -> 1000 | F19: =4000*22% -> 880 | G19: =1038.29/12 -> 86.524167 | H19: =SUM(E19:G19) -> 1966.5242
A20: =ROW()-3 -> 17 | B20: 1155 | C20: =VLOOKUP(B20,'[1]اسماء الموظفين'!$B$8:$O$1001,2,0) -> ساره ناصر سليمان الوهيبي | D20: =VLOOKUP(B20,'[2]المقيمين النشطين'!$B$2:$Q$387,15,0) -> شركة أدفان للصناعة ( شركة شخص واحد ) | E20: =VLOOKUP(B20,[3]سعودة!$B$9:$E$504,4,0) -> 1000 | F20: =4000*22% -> 880 | H20: =SUM(E20:G20) -> 1880
A21: =ROW()-3 -> 18 | B21: 1156 | C21: =VLOOKUP(B21,'[1]اسماء الموظفين'!$B$8:$O$1001,2,0) -> هديل سليمان صالح المريشد | D21: =VLOOKUP(B21,'[2]المقيمين النشطين'!$B$2:$Q$387,15,0) -> شركة ريال البركة للتجارة | E21: =VLOOKUP(B21,[3]سعودة!$B$9:$E$504,4,0) -> 1000 | F21: =4000*22% -> 880 | H21: =SUM(E21:G21) -> 1880
A22: =ROW()-3 -> 19 | B22: 1161 | C22: =VLOOKUP(B22,'[1]اسماء الموظفين'!$B$8:$O$1001,2,0) -> عبدالمجيد محمد عبدالله النمي | D22: =VLOOKUP(B22,'[2]المقيمين النشطين'!$B$2:$Q$387,15,0) -> شركة ريال البركة للتجارة | E22: =VLOOKUP(B22,[3]سعودة!$B$9:$E$504,4,0) -> 1000 | F22: =4000*22% -> 880 | H22: =SUM(E22:G22) -> 1880
A23: =ROW()-3 -> 20 | B23: 1162 | C23: =VLOOKUP(B23,'[1]اسماء الموظفين'!$B$8:$O$1001,2,0) -> ريم عبدالرحمن صالح الفنتوخ | D23: =VLOOKUP(B23,'[2]المقيمين النشطين'!$B$2:$Q$387,15,0) -> شركة أدفان للصناعة ( شركة شخص واحد ) | E23: =VLOOKUP(B23,[3]سعودة!$B$9:$E$504,4,0) -> 1000 | F23: =4000*22% -> 880 | H23: =SUM(E23:G23) -> 1880
A24: =ROW()-3 -> 21 | B24: 1163 | C24: =VLOOKUP(B24,'[1]اسماء الموظفين'!$B$8:$O$1001,2,0) -> لطيفه عبدالله عبدالرحمن رشيد | D24: =VLOOKUP(B24,'[2]المقيمين النشطين'!$B$2:$Q$387,15,0) -> شركة ريال البركة للتجارة | E24: =VLOOKUP(B24,[3]سعودة!$B$9:$E$504,4,0) -> 1500 | F24: =4000*22% -> 880 | H24: =SUM(E24:G24) -> 2380
A25: =ROW()-3 -> 22 | B25: 1202 | C25: =VLOOKUP(B25,'[1]اسماء الموظفين'!$B$8:$O$1001,2,0) -> اثير إبراهيم سعود العبودي | D25: =VLOOKUP(B25,'[2]المقيمين النشطين'!$B$2:$Q$387,15,0) -> مصنع سلطان عبدالرحمن صالح الرزيحي للمنتجات الورقية | E25: =VLOOKUP(B25,[3]سعودة!$B$9:$E$504,4,0) -> 1000 | F25: =4000*22% -> 880 | G25: =806.64/12 -> 67.22 | H25: =SUM(E25:G25) -> 1947.22
A26: =ROW()-3 -> 23 | B26: 1203 | C26: =VLOOKUP(B26,'[1]اسماء الموظفين'!$B$8:$O$1001,2,0) -> منال عبدالعزيز ابراهيم الطلاسي | D26: =VLOOKUP(B26,'[2]المقيمين النشطين'!$B$2:$Q$387,15,0) -> مصنع سلطان عبدالرحمن صالح الرزيحي للمنتجات الورقية | E26: =VLOOKUP(B26,[3]سعودة!$B$9:$E$504,4,0) -> 1000 | F26: =4000*22% -> 880 | H26: =SUM(E26:G26) -> 1880
A27: =ROW()-3 -> 24 | B27: 1254 | C27: =VLOOKUP(B27,'[1]اسماء الموظفين'!$B$8:$O$1001,2,0) -> نوف حسن عبدالله قعود | D27: =VLOOKUP(B27,'[2]المقيمين النشطين'!$B$2:$Q$387,15,0) -> شركة ريال البركة للتجارة | E27: =VLOOKUP(B27,[3]سعودة!$B$9:$E$504,4,0) -> 1120 | F27: =4000*22% -> 880 | H27: =SUM(E27:G27) -> 2000
A28: =ROW()-3 -> 25 | B28: 1274 | C28: =VLOOKUP(B28,'[1]اسماء الموظفين'!$B$8:$O$1001,2,0) -> منصور محمد يحي حكمي | D28: =VLOOKUP(B28,'[2]المقيمين النشطين'!$B$2:$Q$387,15,0) -> شركة ريال البركة للتجارة | E28: =VLOOKUP(B28,[3]سعودة!$B$9:$E$504,4,0) -> 1000 | F28: =4000*22% -> 880 | H28: =SUM(E28:G28) -> 1880
A29: =ROW()-3 -> 26 | B29: 1277 | C29: =VLOOKUP(B29,'[1]اسماء الموظفين'!$B$8:$O$1001,2,0) -> منى احمد محمد السميح | D29: =VLOOKUP(B29,'[2]المقيمين النشطين'!$B$2:$Q$387,15,0) -> شركة ريال البركة للتجارة | E29: =VLOOKUP(B29,[3]سعودة!$B$9:$E$504,4,0) -> 1000 | F29: =4000*22% -> 880 | H29: =SUM(E29:G29) -> 1880
A30: =ROW()-3 -> 27 | B30: 1284 | C30: =VLOOKUP(B30,'[1]اسماء الموظفين'!$B$8:$O$1001,2,0) -> نوره محمد عبدالله النمي | D30: =VLOOKUP(B30,'[2]المقيمين النشطين'!$B$2:$Q$387,15,0) -> شركة ريال البركة للتجارة | E30: =VLOOKUP(B30,[3]سعودة!$B$9:$E$504,4,0) -> 1000 | F30: =4000*22% -> 880 | H30: =SUM(E30:G30) -> 1880
A31: =ROW()-3 -> 28 | B31: 1298 | C31: =VLOOKUP(B31,'[1]اسماء الموظفين'!$B$8:$O$1001,2,0) -> احلام ذياب يوسف الزهراني | D31: =VLOOKUP(B31,'[2]المقيمين النشطين'!$B$2:$Q$387,15,0) -> شركة ريال البركة للتجارة | E31: =VLOOKUP(B31,[3]سعودة!$B$9:$E$504,4,0) -> 1000 | F31: =4000*22% -> 880 | H31: =SUM(E31:G31) -> 1880
A32: =ROW()-3 -> 29 | B32: 1301 | C32: =VLOOKUP(B32,'[1]اسماء الموظفين'!$B$8:$O$1001,2,0) -> وعد سعد عبدالله الهويمل | D32: =VLOOKUP(B32,'[2]المقيمين النشطين'!$B$2:$Q$387,15,0) -> شركة ريال البركة للتجارة | E32: =VLOOKUP(B32,[3]سعودة!$B$9:$E$504,4,0) -> 1000 | F32: =4000*22% -> 880 | H32: =SUM(E32:G32) -> 1880
A33: =ROW()-3 -> 30 | B33: 1302 | C33: =VLOOKUP(B33,'[1]اسماء الموظفين'!$B$8:$O$1001,2,0) -> خلود عبدالرحمن سعود الجبيرى | D33: =VLOOKUP(B33,'[2]المقيمين النشطين'!$B$2:$Q$387,15,0) -> شركة ريال البركة للتجارة | E33: =VLOOKUP(B33,[3]سعودة!$B$9:$E$504,4,0) -> 1000 | F33: =4000*22% -> 880 | H33: =SUM(E33:G33) -> 1880
A34: =ROW()-3 -> 31 | B34: 1306 | C34: =VLOOKUP(B34,'[1]اسماء الموظفين'!$B$8:$O$1001,2,0) -> الهام سليمان فهد الطريمان | D34: =VLOOKUP(B34,'[2]المقيمين النشطين'!$B$2:$Q$387,15,0) -> شركة ريال البركة للتجارة | E34: =VLOOKUP(B34,[3]سعودة!$B$9:$E$504,4,0) -> 1000 | F34: =4000*22% -> 880 | H34: =SUM(E34:G34) -> 1880
A35: =ROW()-3 -> 32 | B35: 1307 | C35: =VLOOKUP(B35,'[1]اسماء الموظفين'!$B$8:$O$1001,2,0) -> وفاء عبدالرحمن سعود الجبيرى | D35: =VLOOKUP(B35,'[2]المقيمين النشطين'!$B$2:$Q$387,15,0) -> شركة ريال البركة للتجارة | E35: =VLOOKUP(B35,[3]سعودة!$B$9:$E$504,4,0) -> 1000 | F35: =4000*22% -> 880 | H35: =SUM(E35:G35) -> 1880
A36: =ROW()-3 -> 33 | B36: 1308 | C36: =VLOOKUP(B36,'[1]اسماء الموظفين'!$B$8:$O$1001,2,0) -> رولا سعد عبدالله بن هويمل | D36: =VLOOKUP(B36,'[2]المقيمين النشطين'!$B$2:$Q$387,15,0) -> شركة ريال البركة للتجارة | E36: =VLOOKUP(B36,[3]سعودة!$B$9:$E$504,4,0) -> 1000 | F36: =4000*22% -> 880 | H36: =SUM(E36:G36) -> 1880
A37: =ROW()-3 -> 34 | B37: 1350 | C37: =VLOOKUP(B37,'[1]اسماء الموظفين'!$B$8:$O$1001,2,0) -> رقيه علي مهدي سماني | D37: =VLOOKUP(B37,'[2]المقيمين النشطين'!$B$2:$Q$387,15,0) -> مؤسسة سلطان عبدالرحمن صالح الرزيحي للتجارة | E37: =VLOOKUP(B37,[3]سعودة!$B$9:$E$504,4,0) -> 1000 | F37: =4000*22% -> 880 | H37: =SUM(E37:G37) -> 1880
... A59: =ROW()-3 -> 56 | B59: 1392 | C59: =VLOOKUP(B59,'[1]اسماء الموظفين'!$B$8:$O$1001,2,0) -> زينب محمد مغيض الحايطي | D59: =VLOOKUP(B59,'[2]المقيمين النشطين'!$B$2:$Q$387,15,0) -> مؤسسة عبدالرحمن سلطان عبدالرحمن الرزيحي للتجارة | E59: =VLOOKUP(B59,[3]سعودة!$B$9:$E$504,4,0) -> 1200 | F59: =4000*22% -> 880 | H59: =SUM(E59:G59) -> 2080
A60: =ROW()-3 -> 57 | B60: 1406 | C60: =VLOOKUP(B60,'[1]اسماء الموظفين'!$B$8:$O$1001,2,0) -> مها ناصر سعد المهيدي | D60: =VLOOKUP(B60,'[2]المقيمين النشطين'!$B$2:$Q$1000,15,0) -> شركة ريال البركة للتجارة | E60: =VLOOKUP(B60,[3]سعودة!$B$9:$E$504,4,0) -> 1000 | F60: =4000*22% -> 880 | H60: =SUM(E60:G60) -> 1880
A61: =ROW()-3 -> 58 | B61: 1435 | C61: =VLOOKUP(B61,'[1]اسماء الموظفين'!$B$8:$O$1001,2,0) -> شما عبدالعزيز عبدالرحمن آل عتيق | D61: شركة أدفان للصناعة ( شركة شخص واحد ) | E61: 0 | F61: 880 | H61: =SUM(E61:G61) -> 880
A62: =ROW()-3 -> 59
...

Sheet تكاليف المقيمين
A1: كشف تكاليف الموظفين
C2: 44197 | E2: =TODAY() -> 45228
A3: م | B3: الرقم الوظيفي | C3: أسم الموظف | D3: الجنسية | E3: الشركة | F3: المشروع | G3: الراتب | H3: اشتراك التامينات الاجتماعية | I3: التأمين الطبي | J3: الشهادة الصحية | K3: تكلفة الأجازة | L3: نهاية الخدمة | M3: تذاكر طيران | N3: نقل الكفالة | O3: جوازات | P3: رخصة العمل | Q3: تأشيرة الخروج والعودة | R3: تحمل نسبة السعودة | S3: مجموج شهري | T3: مجموع سنوي
A4: 2 | B4: 1000 | C4: =VLOOKUP(B4,'[1]اسماء الموظفين'!$B$8:$O$501,2,0) -> سلطان عبدالرحمن صالح الرزيحي | D4: =VLOOKUP(B4,'[1]اسماء الموظفين'!$B$8:$O$501,4,0) -> سعودي | E4: =VLOOKUP(B4,'[2]المقيمين النشطين'!$B$2:$Q$980,15,0) -> المالك | F4: =VLOOKUP(B4,'[1]اسماء الموظفين'!$B$8:$O$501,11,0) -> الإدارة | G4: =VLOOKUP(B4,'[3]رواتب الموظفين 2022'!$B$9:$J$1019,9,0) -> 90000 | H4: 0 | I4: 0 | J4: 0 | K4: 0 | L4: 0 | M4: 0 | O4: 0 | P4: 0 | Q4: 0 | R4: 0 | S4: =SUM(G4:R4) -> 90000 | T4: =S4*12 -> 1080000
A5: =ROW()-3 -> 2 | B5: 1001 | C5: =VLOOKUP(B5,'[1]اسماء الموظفين'!$B$8:$O$501,2,0) -> سنوار عبد المجيد | D5: =VLOOKUP(B5,'[1]اسماء الموظفين'!$B$8:$O$501,4,0) -> بنجلاديش | E5: =VLOOKUP(B5,'[2]المقيمين النشطين'!$B$2:$Q$980,15,0) -> شركة ريال البركة للتجارة | F5: =VLOOKUP(B5,'[1]اسماء الموظفين'!$B$8:$O$501,11,0) -> النسيم | G5: =VLOOKUP(B5,'[3]رواتب الموظفين 2022'!$B$9:$J$1019,9,0) -> 2500 | H5: =VLOOKUP(B5,'[3]رواتب الموظفين 2022'!$B$9:$E$438,4,0)*2% -> 36 | I5: =844/12 -> 70.333333 | J5: 0 | K5: =G5/30*21/12 -> 145.83333 | L5: =G5/2/12 -> 104.16667 | M5: =1800/24 -> 75 | O5: =650/12 -> 54.166667 | P5: =9700/12 -> 808.33333 | Q5: =VLOOKUP(B5,[4]بيان!$B$6:$G$112,4,0) -> 291.66667 | R5: =$K$329 -> 739.31703 | S5: =SUM(G5:R5) -> 4824.817 | T5: =S5*12 -> 57897.804
A6: =ROW()-3 -> 3 | B6: 1002 | C6: =VLOOKUP(B6,'[1]اسماء الموظفين'!$B$8:$O$501,2,0) -> عبدالرحمن محمد عبده السلمي | D6: =VLOOKUP(B6,'[1]اسماء الموظفين'!$B$8:$O$501,4,0) -> اليمن | E6: =VLOOKUP(B6,'[2]المقيمين النشطين'!$B$2:$Q$980,15,0) -> شركة ريال البركة للتجارة | F6: =VLOOKUP(B6,'[1]اسماء الموظفين'!$B$8:$O$501,11,0) -> جملة ريال البركة | G6: =VLOOKUP(B6,'[3]رواتب الموظفين 2022'!$B$9:$J$1019,9,0) -> 10000 | H6: =VLOOKUP(B6,'[3]رواتب الموظفين 2022'!$B$9:$E$438,4,0)*2% -> 72 | I6: =773+1958/12 -> 936.16667 | J6: 0 | K6: =G6/30*21/12 -> 583.33333 | L6: =G6/2/12 -> 416.66667 | M6: =1800/24 -> 75 | O6: =650/12 -> 54.166667 | P6: =9700/12 -> 808.33333 | Q6: =12000/12 -> 1000 | R6: =$K$329 -> 739.31703 | S6: =SUM(G6:R6) -> 14684.984 | T6: =S6*12 -> 176219.8
A7: =ROW()-3 -> 4 | B7: 1003 | C7: =VLOOKUP(B7,'[1]اسماء الموظفين'!$B$8:$O$501,2,0) -> سليم عبده علي الرعوي | D7: =VLOOKUP(B7,'[1]اسماء الموظفين'!$B$8:$O$501,4,0) -> اليمن | E7: =VLOOKUP(B7,'[2]المقيمين النشطين'!$B$2:$Q$980,15,0) -> شركة ريال البركة للتجارة | F7: =VLOOKUP(B7,'[1]اسماء الموظفين'!$B$8:$O$501,11,0) -> الإدارة | G7: =VLOOKUP(B7,'[3]رواتب الموظفين 2022'!$B$9:$J$1019,9,0) -> 10000 | H7: =VLOOKUP(B7,'[3]رواتب الموظفين 2022'!$B$9:$E$438,4,0)*2% -> 72 | I7: =533+520+773+2233/12 -> 2012.0833 | J7: 0 | K7: =G7/30*21/12 -> 583.33333 | L7: =G7/2/12 -> 416.66667 | M7: =1500/12 -> 125 | O7: =650/12 -> 54.166667 | P7: =9700/12 -> 808.33333 | Q7: =12000/12 -> 1000 | R7: =$K$329 -> 739.31703 | S7: =SUM(G7:R7) -> 15810.9 | T7: =S7*12 -> 189730.8
A8: =ROW()-3 -> 5 | B8: 1004 | C8: =VLOOKUP(B8,'[1]اسماء الموظفين'!$B$8:$O$501,2,0) -> مصطفى عبده علي صالح | D8: =VLOOKUP(B8,'[1]اسماء الموظفين'!$B$8:$O$501,4,0) -> اليمن | E8: =VLOOKUP(B8,'[2]المقيمين النشطين'!$B$2:$Q$980,15,0) -> شركة ريال البركة للتجارة | F8: =VLOOKUP(B8,'[1]اسماء الموظفين'!$B$8:$O$501,11,0) -> جملة ريال البركة | G8: =VLOOKUP(B8,'[3]رواتب الموظفين 2022'!$B$9:$J$1019,9,0) -> 8000 | H8: =VLOOKUP(B8,'[3]رواتب الموظفين 2022'!$B$9:$E$438,4,0)*2% -> 72 | I8: =773/12 -> 64.416667 | J8: 0 | K8: =G8/30*21/12 -> 466.66667 | L8: =G8/2/12 -> 333.33333 | M8: =1500/24 -> 62.5 | O8: =650/12 -> 54.166667 | P8: =9700/12 -> 808.33333 | Q8: =VLOOKUP(B8,[4]بيان!$B$6:$G$112,4,0) -> 96.491228 | R8: =$K$329 -> 739.31703 | S8: =SUM(G8:R8) -> 10697.225 | T8: =S8*12 -> 128366.7
A9: =ROW()-3 -> 6 | B9: 1005 | C9: =VLOOKUP(B9,'[1]اسماء الموظفين'!$B$8:$O$501,2,0) -> عبدالسلام محمد سعيد ناجي | D9: =VLOOKUP(B9,'[1]اسماء الموظفين'!$B$8:$O$501,4,0) -> اليمن | E9: =VLOOKUP(B9,'[2]المقيمين النشطين'!$B$2:$Q$980,15,0) -> مؤسسة سلطان عبدالرحمن صالح الرزيحي للتجارة | F9: =VLOOKUP(B9,'[1]اسماء الموظفين'!$B$8:$O$501,11,0) -> جملة سلطان/السويلم | G9: =VLOOKUP(B9,'[3]رواتب الموظفين 2022'!$B$9:$J$1019,9,0) -> 4500 | H9: =VLOOKUP(B9,'[3]رواتب الموظفين 2022'!$B$9:$E$438,4,0)*2% -> 50 | I9: =542.14+642/12 -> 595.64 | J9: 0 | K9: =G9/30*21/12 -> 262.5 | L9: =G9/2/12 -> 187.5 | M9: =1500/24 -> 62.5 | O9: =650/12 -> 54.166667 | P9: =9700/12 -> 808.33333 | Q9: =VLOOKUP(B9,[4]بيان!$B$6:$G$112,4,0) -> 312.5 | R9: =$K$329 -> 739.31703 | S9: =SUM(G9:R9) -> 7572.457 | T9: =S9*12 -> 90869.484
A10: =ROW()-3 -> 7 | B10: 1006 | C10: =VLOOKUP(B10,'[1]اسماء الموظفين'!$B$8:$O$501,2,0) -> بلال صالح حمود الفهد | D10: =VLOOKUP(B10,'[1]اسماء الموظفين'!$B$8:$O$501,4,0) -> اليمن | E10: =VLOOKUP(B10,'[2]المقيمين النشطين'!$B$2:$Q$980,15,0) -> شركة ريال البركة للتجارة | F10: =VLOOKUP(B10,'[1]اسماء الموظفين'!$B$8:$O$501,11,0) -> النسيم 2 | G10: =VLOOKUP(B10,'[3]رواتب الموظفين 2022'!$B$9:$J$1019,9,0) -> 2800 | H10: =VLOOKUP(B10,'[3]رواتب الموظفين 2022'!$B$9:$E$438,4,0)*2% -> 40 | I10: =550.02/12 -> 45.835 | J10: =220/12 -> 18.333333 | K10: =G10/30*21/12 -> 163.33333 | L10: =G10/2/12 -> 116.66667 | M10: =1500/24 -> 62.5 | O10: =650/12 -> 54.166667 | P10: =9700/12 -> 808.33333 | Q10: =VLOOKUP(B10,[4]بيان!$B$6:$G$112,4,0) -> 187.5 | R10: =$K$329 -> 739.31703 | S10: =SUM(G10:R10) -> 5035.9854 | T10: =S10*12 -> 60431.824
A11: =ROW()-3 -> 8 | B11: 1007 | C11: =VLOOKUP(B11,'[1]اسماء الموظفين'!$B$8:$O$501,2,0) -> محمد عبدالدائم محمد عبدالرحمن | D11: =VLOOKUP(B11,'[1]اسماء الموظفين'!$B$8:$O$501,4,0) -> اليمن | E11: =VLOOKUP(B11,'[2]المقيمين النشطين'!$B$2:$Q$980,15,0) -> شركة ريال البركة للتجارة | F11: =VLOOKUP(B11,'[1]اسماء الموظفين'!$B$8:$O$501,11,0) -> مستودع عكاظ 23 | G11: =VLOOKUP(B11,'[3]رواتب الموظفين 2022'!$B$9:$J$1019,9,0) -> 1000 | H11: =VLOOKUP(B11,'[3]رواتب الموظفين 2022'!$B$9:$E$438,4,0)*2% -> 20 | I11: =773+533+1958+623/12 -> 3315.9167 | J11: 0 | K11: 0 | L11: 0 | M11: 0 | O11: 0 | P11: 0 | Q11: 0 | R11: =$K$329 -> 739.31703 | S11: =SUM(G11:R11) -> 5075.2337 | T11: =S11*12 -> 60902.804
A12: =ROW()-3 -> 9 | B12: 1009 | C12: =VLOOKUP(B12,'[1]اسماء الموظفين'!$B$8:$O$501,2,0) -> اسد الزمان علي | D12: =VLOOKUP(B12,'[1]اسماء الموظفين'!$B$8:$O$501,4,0) -> بنجلاديش | E12: =VLOOKUP(B12,'[2]المقيمين النشطين'!$B$2:$Q$980,15,0) -> شركة ريال البركة للتجارة | F12: =VLOOKUP(B12,'[1]اسماء الموظفين'!$B$8:$O$501,11,0) -> أونلاين | G12: =VLOOKUP(B12,'[3]رواتب الموظفين 2022'!$B$9:$J$1019,9,0) -> 2200 | H12: =VLOOKUP(B12,'[3]رواتب الموظفين 2022'!$B$9:$E$438,4,0)*2% -> 32 | I12: =1229/12 -> 102.41667 | J12: 0 | K12: =G12/30*21/12 -> 128.33333 | L12: =G12/2/12 -> 91.666667 | M12: =1800/24 -> 75 | O12: =650/12 -> 54.166667 | P12: =9700/12 -> 808.33333 | Q12: =VLOOKUP(B12,[4]بيان!$B$6:$G$112,4,0) -> 96.491228 | R12: =$K$329 -> 739.31703 | S12: =SUM(G12:R12) -> 4327.7249 | T12: =S12*12 -> 51932.699
A13: =ROW()-3 -> 10 | B13: 1010 | C13: =VLOOKUP(B13,'[1]اسماء الموظفين'!$B$8:$O$501,2,0) -> تفضل ولي | D13: =VLOOKUP(B13,'[1]اسماء الموظفين'!$B$8:$O$501,4,0) -> بنجلاديش | E13: =VLOOKUP(B13,'[2]المقيمين النشطين'!$B$2:$Q$980,15,0) -> مؤسسة سلطان عبدالرحمن صالح الرزيحي للتجارة | F13: =VLOOKUP(B13,'[1]اسماء الموظفين'!$B$8:$O$501,11,0) -> جملة سلطان/السويلم | G13: =VLOOKUP(B13,'[3]رواتب الموظفين 2022'!$B$9:$J$1019,9,0) -> 2200 | H13: =VLOOKUP(B13,'[3]رواتب الموظفين 2022'!$B$9:$E$438,4,0)*2% -> 32 | I13: =1237.07/12 -> 103.08917 | J13: 0 | K13: =G13/30*21/12 -> 128.33333 | L13: =G13/2/12 -> 91.666667 | M13: =1800/24 -> 75 | O13: =650/12 -> 54.166667 | P13: =9700/12 -> 808.33333 | Q13: =VLOOKUP(B13,[4]بيان!$B$6:$G$112,4,0) -> 312.5 | R13: =$K$329 -> 739.31703 | S13: =SUM(G13:R13) -> 4544.4062 | T13: =S13*12 -> 54532.874
A14: =ROW()-3 -> 11 | B14: 1011 | C14: =VLOOKUP(B14,'[1]اسماء الموظفين'!$B$8:$O$501,2,0) -> أيمن محمد فتحي خلف | D14: =VLOOKUP(B14,'[1]اسماء الموظفين'!$B$8:$O$501,4,0) -> مصر | E14: =VLOOKUP(B14,'[2]المقيمين النشطين'!$B$2:$Q$980,15,0) -> دوام جزئي | F14: =VLOOKUP(B14,'[1]اسماء الموظفين'!$B$8:$O$501,11,0) -> الإدارة | G14: =VLOOKUP(B14,'[3]رواتب الموظفين 2022'!$B$9:$J$1019,9,0) -> 3000 | H14: 0 | I14: 0 | J14: 0 | K14: 0 | L14: 0 | M14: 0 | N14: 0 | O14: 0 | P14: 0 | Q14: 0 | R14: 0 | S14: =SUM(G14:R14) -> 3000 | T14: =S14*12 -> 36000
A15: =ROW()-3 -> 12 | B15: 1012 | C15: =VLOOKUP(B15,'[1]اسماء الموظفين'!$B$8:$O$501,2,0) -> نوبي امير شيخ | D15: =VLOOKUP(B15,'[1]اسماء الموظفين'!$B$8:$O$501,4,0) -> الهند | E15: =VLOOKUP(B15,'[2]المقيمين النشطين'!$B$2:$Q$980,15,0) -> شركة ريال البركة للتجارة | F15: =VLOOKUP(B15,'[1]اسماء الموظفين'!$B$8:$O$501,11,0) -> العنود | G15: =VLOOKUP(B15,'[3]رواتب الموظفين 2022'!$B$9:$J$1019,9,0) -> 1900 | H15: =VLOOKUP(B15,'[3]رواتب الموظفين 2022'!$B$9:$E$438,4,0)*2% -> 28 | I15: =480/12 -> 40 | J15: 0 | K15: =G15/30*21/12 -> 110.83333 | L15: =G15/2/12 -> 79.166667 | M15: =1800/24 -> 75 | O15: =650/12 -> 54.166667 | P15: =9700/12 -> 808.33333 | Q15: =VLOOKUP(B15,[4]بيان!$B$6:$G$112,4,0) -> 325 | R15: =$K$329 -> 739.31703 | S15: =SUM(G15:R15) -> 4159.817 | T15: =S15*12 -> 49917.804
A16: =ROW()-3 -> 13 | B16: 1015 | C16: =VLOOKUP(B16,'[1]اسماء الموظفين'!$B$8:$O$501,2,0) -> عجيب بيلافي | D16: =VLOOKUP(B16,'[1]اسماء الموظفين'!$B$8:$O$501,4,0) -> الهند | E16: =VLOOKUP(B16,'[2]المقيمين النشطين'!$B$2:$Q$980,15,0) -> شركة ريال البركة للتجارة | F16: =VLOOKUP(B16,'[1]اسماء الموظفين'!$B$8:$O$501,11,0) -> جملة ريال البركة | G16: =VLOOKUP(B16,'[3]رواتب الموظفين 2022'!$B$9:$J$1019,9,0) -> 2500 | H16: =VLOOKUP(B16,'[3]رواتب الموظفين 2022'!$B$9:$E$438,4,0)*2% -> 32 | I16: =145.38/12 -> 12.115 | J16: 0 | K16: =G16/30*21/12 -> 145.83333 | L16: =G16/2/12 -> 104.16667 | M16: =1800/24 -> 75 | O16: =650/12 -> 54.166667 | P16: =9700/12 -> 808.33333 | Q16: =VLOOKUP(B16,[4]بيان!$B$6:$G$112,4,0) -> 96.491228 | R16: =$K$329 -> 739.31703 | S16: =SUM(G16:R16) -> 4567.4233 | T16: =S16*12 -> 54809.079
A17: =ROW()-3 -> 14 | B17: 1016 | C17: =VLOOKUP(B17,'[1]اسماء الموظفين'!$B$8:$O$501,2,0) -> معشوق أحمد أنصاري | D17: =VLOOKUP(B17,'[1]اسماء الموظفين'!$B$8:$O$501,4,0) -> هندي | E17: =VLOOKUP(B17,'[2]المقيمين النشطين'!$B$2:$Q$980,15,0) -> سعد عبدالرحمن صالح الرزيحي | F17: =VLOOKUP(B17,'[1]اسماء الموظفين'!$B$8:$O$501,11,0) -> الإستراحة | G17: =VLOOKUP(B17,'[3]رواتب الموظفين 2022'!$B$9:$J$1019,9,0) -> 1800 | H17: 0 | I17: 0 | J17: 0 | K17: =G17/30*21/12 -> 105 | L17: =G17/2/12 -> 75 | M17: =1800/24 -> 75 | O17: =600/12 -> 50 | Q17: 0 | R17: 0 | S17: =SUM(G17:R17) -> 2105 | T17: =S17*12 -> 25260
A18: =ROW()-3 -> 15 | B18: 1017 | C18: =VLOOKUP(B18,'[1]اسماء الموظفين'!$B$8:$O$501,2,0) -> جهانقير عبد الرزاق بادي | D18: =VLOOKUP(B18,'[1]اسماء الموظفين'!$B$8:$O$501,4,0) -> بنجلاديش | E18: =VLOOKUP(B18,'[2]المقيمين النشطين'!$B$2:$Q$980,15,0) -> شركة ريال البركة للتجارة | F18: =VLOOKUP(B18,'[1]اسماء الموظفين'!$B$8:$O$501,11,0) -> الدائري الغربي | G18: =VLOOKUP(B18,'[3]رواتب الموظفين 2022'!$B$9:$J$1019,9,0) -> 2000 | H18: =VLOOKUP(B18,'[3]رواتب الموظفين 2022'!$B$9:$E$438,4,0)*2% -> 26 | I18: =367/12 -> 30.583333 | J18: 0 | K18: =G18/30*21/12 -> 116.66667 | L18: =G18/2/12 -> 83.333333 | M18: =1800/24 -> 75 | O18: =650/12 -> 54.166667 | P18: =9700/12 -> 808.33333 | Q18: =VLOOKUP(B18,[4]بيان!$B$6:$G$112,4,0) -> 291.66667 | R18: =$K$329 -> 739.31703 | S18: =SUM(G18:R18) -> 4225.067 | T18: =S18*12 -> 50700.804
A19: =ROW()-3 -> 16 | B19: 1018 | C19: =VLOOKUP(B19,'[1]اسماء الموظفين'!$B$8:$O$501,2,0) -> محمد عبدالله محمد الحبجي | D19: =VLOOKUP(B19,'[1]اسماء الموظفين'!$B$8:$O$501,4,0) -> اليمن | E19: =VLOOKUP(B19,'[2]المقيمين النشطين'!$B$2:$Q$980,15,0) -> شركة ريال البركة للتجارة | F19: =VLOOKUP(B19,'[1]اسماء الموظفين'!$B$8:$O$501,11,0) -> الإدارة | G19: =VLOOKUP(B19,'[3]رواتب الموظفين 2022'!$B$9:$J$1019,9,0) -> 5500 | H19: =VLOOKUP(B19,'[3]رواتب الموظفين 2022'!$B$9:$E$438,4,0)*2% -> 44 | J19: 0 | K19: =G19/30*21/12 -> 320.83333 | L19: =G19/2/12 -> 229.16667 | M19: =1500/12 -> 125 | O19: =650/12 -> 54.166667 | P19: =9700/12 -> 808.33333 | Q19: 0 | R19: =$K$329 -> 739.31703 | S19: =SUM(G19:R19) -> 7820.817 | T19: =S19*12 -> 93849.804
A20: =ROW()-3 -> 17 | B20: 1019 | C20: =VLOOKUP(B20,'[1]اسماء الموظفين'!$B$8:$O$501,2,0) -> رؤوف انصاري سفيدة | D20: =VLOOKUP(B20,'[1]اسماء الموظفين'!$B$8:$O$501,4,0) -> نيبال | E20: =VLOOKUP(B20,'[2]المقيمين النشطين'!$B$2:$Q$980,15,0) -> شركة ريال البركة للتجارة | F20: =VLOOKUP(B20,'[1]اسماء الموظفين'!$B$8:$O$501,11,0) -> المصنع | G20: =VLOOKUP(B20,'[3]رواتب الموظفين 2022'!$B$9:$J$1019,9,0) -> 2000 | H20: =VLOOKUP(B20,'[3]رواتب الموظفين 2022'!$B$9:$E$438,4,0)*2% -> 28 | I20: =480/12 -> 40 | J20: =1251.55/12 -> 104.29583 | K20: =G20/30*21/12 -> 116.66667 | L20: =G20/2/12 -> 83.333333 | M20: =1800/24 -> 75 | O20: =650/12 -> 54.166667 | P20: =9700/12 -> 808.33333 | Q20: 0 | R20: =$K$329 -> 739.31703 | S20: =SUM(G20:R20) -> 4049.1129 | T20: =S20*12 -> 48589.354
A21: =ROW()-3 -> 18 | B21: 1020 | C21: =VLOOKUP(B21,'[1]اسماء الموظفين'!$B$8:$O$501,2,0) -> محمد فاروق خليل | D21: =VLOOKUP(B21,'[1]اسماء الموظفين'!$B$8:$O$501,4,0) -> الهند | E21: =VLOOKUP(B21,'[2]المقيمين النشطين'!$B$2:$Q$980,15,0) -> عبدالرحمن سلطان الرزيحي | F21: =VLOOKUP(B21,'[1]اسماء الموظفين'!$B$8:$O$501,11,0) -> المصنع | G21: =VLOOKUP(B21,'[3]رواتب الموظفين 2022'!$B$9:$J$1019,9,0) -> 1700 | H21: 0 | I21: 0 | J21: 0 | K21: =G21/30*21/12 -> 99.166667 | L21: =G21/2/12 -> 70.833333 | M21: =1800/24 -> 75 | O21: =650/12 -> 54.166667 | P21: 0 | Q21: 0 | R21: 0 | S21: =SUM(G21:R21) -> 1999.1667 | T21: =S21*12 -> 23990
A22: =ROW()-3 -> 19 | B22: 1021 | C22: =VLOOKUP(B22,'[1]اسماء الموظفين'!$B$8:$O$501,2,0) -> ياسر عبدالولي قايد الغابري | D22: =VLOOKUP(B22,'[1]اسماء الموظفين'!$B$8:$O$501,4,0) -> اليمن | E22: =VLOOKUP(B22,'[2]المقيمين النشطين'!$B$2:$Q$980,15,0) -> شركة ريال البركة للتجارة | F22: =VLOOKUP(B22,'[1]اسماء الموظفين'!$B$8:$O$501,11,0) -> وكالة ممكن | G22: =VLOOKUP(B22,'[3]رواتب الموظفين 2022'!$B$9:$J$1019,9,0) -> 8000 | H22: =VLOOKUP(B22,'[3]رواتب الموظفين 2022'!$B$9:$E$438,4,0)*2% -> 72 | I22: =1824+517/12 -> 1867.0833 | J22: 0 | K22: =G22/30*21/12 -> 466.66667 | L22: =G22/2/12 -> 333.33333 | M22: =1500/12 -> 125 | O22: =650/12 -> 54.166667 | P22: =9700/12 -> 808.33333 | Q22: =7000/12 -> 583.33333 | R22: =$K$329 -> 739.31703 | S22: =SUM(G22:R22) -> 13049.234 | T22: =S22*12 -> 156590.8
A23: =ROW()-3 -> 20 | B23: 1022 | C23: =VLOOKUP(B23,'[1]اسماء الموظفين'!$B$8:$O$501,2,0) -> عمر احمد علي الشامي | D23: =VLOOKUP(B23,'[1]اسماء الموظفين'!$B$8:$O$501,4,0) -> اليمن | E23: =VLOOKUP(B23,'[2]المقيمين النشطين'!$B$2:$Q$980,15,0) -> شركة ريال البركة للتجارة | F23: =VLOOKUP(B23,'[1]اسماء الموظفين'!$B$8:$O$501,11,0) -> جملة ريال البركة | G23: =VLOOKUP(B23,'[3]رواتب الموظفين 2022'!$B$9:$J$1019,9,0) -> 5000 | H23: =VLOOKUP(B23,'[3]رواتب الموظفين 2022'!$B$9:$E$438,4,0)*2% -> 44 | J23: 0 | K23: =G23/30*21/12 -> 291.66667 | L23: =G23/2/12 -> 208.33333 | M23: =1500/24 -> 62.5 | O23: =650/12 -> 54.166667 | P23: =9700/12 -> 808.33333 | Q23: 0 | R23: =$K$329 -> 739.31703 | S23: =SUM(G23:R23) -> 7208.317 | T23: =S23*12 -> 86499.804
A24: =ROW()-3 -> 21 | B24: 1023 | C24: =VLOOKUP(B24,'[1]اسماء الموظفين'!$B$8:$O$501,2,0) -> عبدالرحمن سلطان الرزيحي | D24: =VLOOKUP(B24,'[1]اسماء الموظفين'!$B$8:$O$501,4,0) -> سعودي | E24: =VLOOKUP(B24,'[2]المقيمين النشطين'!$B$2:$Q$980,15,0) -> شركة ريال البركة للتجارة | F24: =VLOOKUP(B24,'[1]اسماء الموظفين'!$B$8:$O$501,11,0) -> الإدارة | G24: =VLOOKUP(B24,'[3]رواتب الموظفين 2022'!$B$9:$J$1019,9,0) -> 65000 | H24: =VLOOKUP(B24,'[3]رواتب الموظفين 2022'!$B$9:$E$438,4,0)*2% -> 192 | I24: 0 | J24: 0 | K24: =G24/30*21/12 -> 3791.6667 | L24: =G24/2/12 -> 2708.3333 | M24: 0 | O24: 0 | P24: 0 | Q24: 0 | R24: 0 | S24: =SUM(G24:R24) -> 71692 | T24: =S24*12 -> 860304
A25: =ROW()-3 -> 22 | B25: 1024 | C25: =VLOOKUP(B25,'[1]اسماء الموظفين'!$B$8:$O$501,2,0) -> إسماعيل دحدوح مياه | D25: =VLOOKUP(B25,'[1]اسماء الموظفين'!$B$8:$O$501,4,0) -> بنجلاديش | E25: =VLOOKUP(B25,'[2]المقيمين النشطين'!$B$2:$Q$980,15,0) -> شركة ريال البركة للتجارة | F25: =VLOOKUP(B25,'[1]اسماء الموظفين'!$B$8:$O$501,11,0) -> جملة ريال البركة | G25: =VLOOKUP(B25,'[3]رواتب الموظفين 2022'!$B$9:$J$1019,9,0) -> 1800 | H25: =VLOOKUP(B25,'[3]رواتب الموظفين 2022'!$B$9:$E$438,4,0)*2% -> 26 | I25: =480/12 -> 40 | J25: 0 | K25: =G25/30*21/12 -> 105 | L25: =G25/2/12 -> 75 | M25: =1800/24 -> 75 | O25: =650/12 -> 54.166667 | P25: =9700/12 -> 808.33333 | Q25: 0 | R25: =$K$329 -> 739.31703 | S25: =SUM(G25:R25) -> 3722.817 | T25: =S25*12 -> 44673.804
A26: =ROW()-3 -> 23 | B26: 1025 | C26: =VLOOKUP(B26,'[1]اسماء الموظفين'!$B$8:$O$501,2,0) -> فرهد حسين | D26: =VLOOKUP(B26,'[1]اسماء الموظفين'!$B$8:$O$501,4,0) -> بنجلاديش | E26: =VLOOKUP(B26,'[2]المقيمين النشطين'!$B$2:$Q$980,15,0) -> شركة ريال البركة للتجارة | F26: =VLOOKUP(B26,'[1]اسماء الموظفين'!$B$8:$O$501,11,0) -> الدائري الغربي | G26: =VLOOKUP(B26,'[3]رواتب الموظفين 2022'!$B$9:$J$1019,9,0) -> 2500 | H26: =VLOOKUP(B26,'[3]رواتب الموظفين 2022'!$B$9:$E$438,4,0)*2% -> 36 | I26: =245/12 -> 20.416667 | J26: =220/12 -> 18.333333 | K26: =G26/30*21/12 -> 145.83333 | L26: =G26/2/12 -> 104.16667 | M26: =1800/24 -> 75 | O26: =650/12 -> 54.166667 | P26: =9700/12 -> 808.33333 | Q26: =VLOOKUP(B26,[4]بيان!$B$6:$G$112,4,0) -> 183.33333 | R26: =$K$329 -> 739.31703 | S26: =SUM(G26:R26) -> 4684.9004 | T26: =S26*12 -> 56218.804
A27: =ROW()-3 -> 24 | B27: 1026 | C27: =VLOOKUP(B27,'[1]اسماء الموظفين'!$B$8:$O$501,2,0) -> أنور حسين | D27: =VLOOKUP(B27,'[1]اسماء الموظفين'!$B$8:$O$501,4,0) -> بنجلاديش | E27: =VLOOKUP(B27,'[2]المقيمين النشطين'!$B$2:$Q$980,15,0) -> شركة ريال البركة للتجارة | F27: =VLOOKUP(B27,'[1]اسماء الموظفين'!$B$8:$O$501,11,0) -> النسيم | G27: =VLOOKUP(B27,'[3]رواتب الموظفين 2022'!$B$9:$J$1019,9,0) -> 1950 | H27: =VLOOKUP(B27,'[3]رواتب الموظفين 2022'!$B$9:$E$438,4,0)*2% -> 26 | I27: =245/12 -> 20.416667 | J27: 0 | K27: =G27/30*21/12 -> 113.75 | L27: =G27/2/12 -> 81.25 | M27: =1800/24 -> 75 | O27: =650/12 -> 54.166667 | P27: =9700/12 -> 808.33333 | Q27: =VLOOKUP(B27,[4]بيان!$B$6:$G$112,4,0) -> 291.66667 | R27: =$K$329 -> 739.31703 | S27: =SUM(G27:R27) -> 4159.9004 | T27: =S27*12 -> 49918.804
